Workbook

Sheet STATS
A1: Date start of operations | B1: 45333 | D1: Gear | E1: Events | F1: Time
B2: 45351 | D2: AT | E2: =COUNTIF(Events!C:C, "*"&D2&"*") -> 6 | F2: =SUMIF(Events!C:C, "*"&D2&"*", Events!K:K) -> 252.5
A3: Days in operations | B3: =B2-B1 -> 18 | D3: NIS | E3: =COUNTIF(Events!C:C, "*"&D3&"*") -> 130 | F3: =SUMIF(Events!C:C, "*"&D3&"*", Events!K:K) -> 0.83263889
A4: Number of Deployments | B4: =COUNTA(Events!C:C) -> 306 | D4: DRM | E4: =COUNTIF(Events!C:C, "*"&D4&"*") -> 11 | F4: =SUMIF(Events!C:C, "*"&D4&"*", Events!K:K) -> 0.50416667
A5: Average deployments/day | B5: =B4/B3 -> 17 | D5: ITD | E5: =COUNTIF(Events!C:C, "*"&D5&"*") -> 2 | F5: =SUMIF(Events!C:C, "*"&D5&"*", Events!K:K) -> 0.03125
A6: Number of Databased Samples | B6: =COUNTA(Samples!A2:A3956) -> 3955 | D6: RD | E6: =COUNTIF(Events!C:C, "*"&D6&"*") -> 15 | F6: =SUMIF(Events!C:C, "*"&D6&"*", Events!K:K) -> 0.20486111
A7: Number of Sample # attributed | B7: =MAX(Events!AA:AB) -> 4317 | D7: ROV | E7: =COUNTIF(Events!C:C, "*"&D7&"*") -> 21 | F7: =SUMIF(Events!C:C, "*"&D7&"*", Events!K:K) -> 0.78611111
A8: Number of Individuals | B8: =SUM(#REF!) -> #REF! | D8: DIV | E8: =COUNTIF(Events!C:C, "*"&D8&"*") -> 42 | F8: =SUMIF(Events!C:C, "*"&D8&"*", Events!K:K) -> 1.2625
A9: Time in Operation (hrs) | B9: =SUM(Events!K:K) -> 670.60694 | D9: ST | E9: =COUNTIF(Events!C:C, "*"&D9&"*") -> 3 | F9: =SUMIF(Events!C:C, "*"&D9&"*", Events!K:K) -> 306.43333
A10: Time in Operation (days) | B10: =B9/24 -> 27.941956 | D10: INC | E10: =COUNTIF(Events!C:C, "*"&D10&"*") -> 4 | F10: =SUMIF(Events!C:C, "*"&D10&"*", Events!K:K) -> 107.91667
D11: TOP | E11: =COUNTIF(Events!C:C, "*"&D11&"*") -> 64 | F11: =SUMIF(Events!C:C, "*"&D11&"*", Events!K:K) -> 0
D12: VV | E12: =COUNTIF(Events!C:C, "*"&D12&"*") -> 6 | F12: =SUMIF(Events!C:C, "*"&D12&"*", Events!K:K) -> 0.11458333
D14: SUM | E14: =SUM(E2:E11) -> 298 | F14: =SUM(F2:F11) -> 670.47153
F15: =SUM(F3:F8,F11,F12) -> 3.7361111

Sheet Calendar
B1: Mon | C1: Tue | D1: Wed | E1: Thu | F1: Fri | G1: Sat | H1: Sun
A2: February | H2: 4
B3: 5 | C3: 6 | D3: 7 | E3: 8 | F3: 9 | G3: 10 | H3: 11
B4: 12 | C4: 13 | D4: 14 | E4: 15 | F4: 16 | G4: 17 | H4: 18
B5: 19 | C5: 20 | D5: 21 | E5: 22 | F5: 23 | G5: 24 | H5: 25
A6: February/March | B6: 26 | C6: 27 | D6: 28 | E6: 29 | F6: 1 | G6: 2 | H6: 3
A7: March | B7: 4 | C7: 5 | D7: 6 | E7: 7 | F7: 8
A9: Mobilisation/Demobilisation
A10: CapeHorn/Drake transit
A11: WAP transit
A12: Work at sea

Sheet Events
A1: locality | B1: higherGeographyID | C1: eventID | D1: gearType | E1: eventDate start | F1: eventDate stop | G1: Time start (UTC-3) | H1: Time end (UTC-3) | I1: eventTime | J1: eventDate | K1: Duration | L1: Collector1 | M1: Collector2 | N1: Collector3 | O1: Collector4 | P1: collector1orcid | Q1: collector2orcid | R1: collector3orcid | S1: collector4orcid | T1: Lat start (dec min) | U1: Long Start (dec min) | V1: Lat Stop (dec min) | W1: Long Stop (dec min) | X1: minimumDepthInMeters | Y1: maximumDepthInMeters | Z1: maximumElevationInMeters | AA1: Sample_Ids Start | AB1: Sample_Ids Stop | AC1: eventRemarks | AD1: Lat Start | AE1: Long Start | AF1: Lat Stop | AG1: Long Stop
A2: Melchior Island, North Omega | B2: https://data.aad.gov.au/aadc/gaz/scar/display_name.cfm?gaz_id=110104 | C2: DIV_1 | D2: =_xlfn.TEXTBEFORE(Table3[[#This Row],[eventID]],"_") -> DIV | E2: 45333 | G2: 0.41319444 | H2: 0.44236111 | I2: 09:55-03:00/10:37-03:00 | J2: 2024-02-11 | K2: =H2-G2 -> 0.029166667 | L2: Martin Dogniez | M2: Lea Katz | N2: Anthony Voisin | P2: =IF(Table3[[#This Row],[Collector1]]="","", _xlfn.LET(_xlpm.x,VLOOKUP(Table3[[#This Row],[Collector1]],'Drop-down_menus'!$F$2:$G$16,2,FALSE),IF(_xlpm.x=0,"",_xlpm.x))) -> https://orcid.org/0000-0002-9708-1761 | Q2: =IF(Table3[[#This Row],[Collector2]]="","", _xlfn.LET(_xlpm.x,VLOOKUP(Table3[[#This Row],[Collector2]],'Drop-down_menus'!$F$2:$G$16,2,FALSE),IF(_xlpm.x=0,"",_xlpm.x))) -> https://orcid.org/0000-0001-5748-602X | R2: =IF(Table3[[#This Row],[Collector3]]="","", _xlfn.LET(_xlpm.x,VLOOKUP(Table3[[#This Row],[Collector3]],'Drop-down_menus'!$F$2:$G$16,2,FALSE),IF(_xlpm.x=0,"",_xlpm.x))) -> https://orcid.org/0000-0003-3696-4445 | S2: =IF(Table3[[#This Row],[Collector4]]="","", _xlfn.LET(_xlpm.x,VLOOKUP(Table3[[#This Row],[Collector4]],'Drop-down_menus'!$F$2:$G$16,2,FALSE),IF(_xlpm.x=0,"",_xlpm.x))) | T2: 64°19,235 | U2: 62°55,418 | Y2: 21 | AA2: 1 | AB2: 70 | AC2: Sea urchins, photography
A3: Melchior Island, North Omega | B3: https://data.aad.gov.au/aadc/gaz/scar/display_name.cfm?gaz_id=110104 | C3: DIV_2 | D3: =_xlfn.TEXTBEFORE(Table3[[#This Row],[eventID]],"_") -> DIV | E3: 45333 | G3: 0.48194444 | H3: 0.51388889 | I3: 11:34-03:00/12:20-03:00 | J3: 2024-02-11 | K3: =H3-G3 -> 0.031944444 | L3: Lucas Terrana | M3: Camille Moreau | P3: =IF(Table3[[#This Row],[Collector1]]="","", _xlfn.LET(_xlpm.x,VLOOKUP(Table3[[#This Row],[Collector1]],'Drop-down_menus'!$F$2:$G$16,2,FALSE),IF(_xlpm.x=0,"",_xlpm.x))) -> https://orcid.org/0000-0001-5767-3220 | Q3: =IF(Table3[[#This Row],[Collector2]]="","", _xlfn.LET(_xlpm.x,VLOOKUP(Table3[[#This Row],[Collector2]],'Drop-down_menus'!$F$2:$G$16,2,FALSE),IF(_xlpm.x=0,"",_xlpm.x))) -> https://orcid.org/0000-0002-0981-7442 | R3: =IF(Table3[[#This Row],[Collector3]]="","", _xlfn.LET(_xlpm.x,VLOOKUP(Table3[[#This Row],[Collector3]],'Drop-down_menus'!$F$2:$G$16,2,FALSE),IF(_xlpm.x=0,"",_xlpm.x))) | S3: =IF(Table3[[#This Row],[Collector4]]="","", _xlfn.LET(_xlpm.x,VLOOKUP(Table3[[#This Row],[Collector4]],'Drop-down_menus'!$F$2:$G$16,2,FALSE),IF(_xlpm.x=0,"",_xlpm.x))) | T3: 64°19,235 | U3: 62°55,418 | Y3: 21 | AA3: 73 | AB3: 92 | AC3: Meiobenthioc cores and incubation cores
A4: Melchior Island, North Omega | B4: https://data.aad.gov.au/aadc/gaz/scar/display_name.cfm?gaz_id=110104 | C4: ST_1 | D4: =_xlfn.TEXTBEFORE(Table3[[#This Row],[eventID]],"_") -> ST | E4: 45333 | F4: 45338 | G4: 0.54027778 | H4: 0.4125 | J4: 2024-02-11T12:58-03:00/2024-02-16T09:54-03:00 | K4: =-((E4+G4)-(F4+H4))*24 -> 116.93333 | L4: Axelle Brusselman | P4: =IF(Table3[[#This Row],[Collector1]]="","", _xlfn.LET(_xlpm.x,VLOOKUP(Table3[[#This Row],[Collector1]],'Drop-down_menus'!$F$2:$G$16,2,FALSE),IF(_xlpm.x=0,"",_xlpm.x))) -> https://orcid.org/0009-0002-6669-2911 | Q4: =IF(Table3[[#This Row],[Collector2]]="","", _xlfn.LET(_xlpm.x,VLOOKUP(Table3[[#This Row],[Collector2]],'Drop-down_menus'!$F$2:$G$16,2,FALSE),IF(_xlpm.x=0,"",_xlpm.x))) | R4: =IF(Table3[[#This Row],[Collector3]]="","", _xlfn.LET(_xlpm.x,VLOOKUP(Table3[[#This Row],[Collector3]],'Drop-down_menus'!$F$2:$G$16,2,FALSE),IF(_xlpm.x=0,"",_xlpm.x))) | S4: =IF(Table3[[#This Row],[Collector4]]="","", _xlfn.LET(_xlpm.x,VLOOKUP(Table3[[#This Row],[Collector4]],'Drop-down_menus'!$F$2:$G$16,2,FALSE),IF(_xlpm.x=0,"",_xlpm.x))) | T4: 64°19,2206 | U4: 62°55,2654 | Y4: 21 | AA4: 1259 | AB4: 1260 | AC4: Deployment
A5: Melchior Island, North Omega | B5: https://data.aad.gov.au/aadc/gaz/scar/display_name.cfm?gaz_id=110104 | C5: NIS_1 | D5: =_xlfn.TEXTBEFORE(Table3[[#This Row],[eventID]],"_") -> NIS | E5: 45333 | G5: 0.69722222 | H5: 0.70833333 | I5: 16:44-03:00/17:00-03:00 | J5: 2024-02-11 | K5: =H5-G5 -> 0.011111111 | L5: Axelle Brusselman | P5: =IF(Table3[[#This Row],[Collector1]]="","", _xlfn.LET(_xlpm.x,VLOOKUP(Table3[[#This Row],[Collector1]],'Drop-down_menus'!$F$2:$G$16,2,FALSE),IF(_xlpm.x=0,"",_xlpm.x))) -> https://orcid.org/0009-0002-6669-2911 | Q5: =IF(Table3[[#This Row],[Collector2]]="","", _xlfn.LET(_xlpm.x,VLOOKUP(Table3[[#This Row],[Collector2]],'Drop-down_menus'!$F$2:$G$16,2,FALSE),IF(_xlpm.x=0,"",_xlpm.x))) | R5: =IF(Table3[[#This Row],[Collector3]]="","", _xlfn.LET(_xlpm.x,VLOOKUP(Table3[[#This Row],[Collector3]],'Drop-down_menus'!$F$2:$G$16,2,FALSE),IF(_xlpm.x=0,"",_xlpm.x))) | S5: =IF(Table3[[#This Row],[Collector4]]="","", _xlfn.LET(_xlpm.x,VLOOKUP(Table3[[#This Row],[Collector4]],'Drop-down_menus'!$F$2:$G$16,2,FALSE),IF(_xlpm.x=0,"",_xlpm.x))) | T5: 64°19,235 | U5: 62°55,418 | Y5: 20 | AA5: 93 | AB5: 137
A6: Melchior Island, North Omega | B6: https://data.aad.gov.au/aadc/gaz/scar/display_name.cfm?gaz_id=110104 | C6: DR_1 | D6: =_xlfn.TEXTBEFORE(Table3[[#This Row],[eventID]],"_") -> DR | E6: 45333 | G6: 0.58333333 | H6: 0.60416667 | I6: 14:00-03:00/14:30-03:00 | J6: 2024-02-11 | K6: =H6-G6 -> 0.020833333 | L6: Bruno Danis | P6: =IF(Table3[[#This Row],[Collector1]]="","", _xlfn.LET(_xlpm.x,VLOOKUP(Table3[[#This Row],[Collector1]],'Drop-down_menus'!$F$2:$G$16,2,FALSE),IF(_xlpm.x=0,"",_xlpm.x))) -> https://orcid.org/0000-0002-9037-7623 | Q6: =IF(Table3[[#This Row],[Collector2]]="","", _xlfn.LET(_xlpm.x,VLOOKUP(Table3[[#This Row],[Collector2]],'Drop-down_menus'!$F$2:$G$16,2,FALSE),IF(_xlpm.x=0,"",_xlpm.x))) | R6: =IF(Table3[[#This Row],[Collector3]]="","", _xlfn.LET(_xlpm.x,VLOOKUP(Table3[[#This Row],[Collector3]],'Drop-down_menus'!$F$2:$G$16,2,FALSE),IF(_xlpm.x=0,"",_xlpm.x))) | S6: =IF(Table3[[#This Row],[Collector4]]="","", _xlfn.LET(_xlpm.x,VLOOKUP(Table3[[#This Row],[Collector4]],'Drop-down_menus'!$F$2:$G$16,2,FALSE),IF(_xlpm.x=0,"",_xlpm.x))) | T6: 64°19,235 | U6: 62°55,418 | Z6: 300
A7: Melchior Island, North Omega | B7: https://data.aad.gov.au/aadc/gaz/scar/display_name.cfm?gaz_id=110104 | C7: AT_1 | D7: =_xlfn.TEXTBEFORE(Table3[[#This Row],[eventID]],"_") -> AT | E7: 45333 | F7: 45335 | G7: 0.72916667 | H7: 0.70833333 | J7: 2024-02-11T17:30-03:00/2024-02-13T17:00-03:00 | K7: =-((E7+G7)-(F7+H7))*24 -> 47.5 | L7: Henri Robert | P7: =IF(Table3[[#This Row],[Collector1]]="","", _xlfn.LET(_xlpm.x,VLOOKUP(Table3[[#This Row],[Collector1]],'Drop-down_menus'!$F$2:$G$16,2,FALSE),IF(_xlpm.x=0,"",_xlpm.x))) | Q7: =IF(Table3[[#This Row],[Collector2]]="","", _xlfn.LET(_xlpm.x,VLOOKUP(Table3[[#This Row],[Collector2]],'Drop-down_menus'!$F$2:$G$16,2,FALSE),IF(_xlpm.x=0,"",_xlpm.x))) | R7: =IF(Table3[[#This Row],[Collector3]]="","", _xlfn.LET(_xlpm.x,VLOOKUP(Table3[[#This Row],[Collector3]],'Drop-down_menus'!$F$2:$G$16,2,FALSE),IF(_xlpm.x=0,"",_xlpm.x))) | S7: =IF(Table3[[#This Row],[Collector4]]="","", _xlfn.LET(_xlpm.x,VLOOKUP(Table3[[#This Row],[Collector4]],'Drop-down_menus'!$F$2:$G$16,2,FALSE),IF(_xlpm.x=0,"",_xlpm.x))) | T7: 64°19,24 | U7: 62°55,25 | Y7: 22 | AC7: Deployment
A8: Melchior Island, North Omega | B8: https://data.aad.gov.au/aadc/gaz/scar/display_name.cfm?gaz_id=110104 | C8: ROV_1 | D8: =_xlfn.TEXTBEFORE(Table3[[#This Row],[eventID]],"_") -> ROV | E8: 45333 | G8: 0.6875 | H8: 0.72916667 | I8: 16:30-03:00/17:30-03:00 | J8: 2024-02-11 | K8: =H8-G8 -> 0.041666667 | L8: Lea Katz | M8: Henri Robert | P8: =IF(Table3[[#This Row],[Collector1]]="","", _xlfn.LET(_xlpm.x,VLOOKUP(Table3[[#This Row],[Collector1]],'Drop-down_menus'!$F$2:$G$16,2,FALSE),IF(_xlpm.x=0,"",_xlpm.x))) -> https://orcid.org/0000-0001-5748-602X | Q8: =IF(Table3[[#This Row],[Collector2]]="","", _xlfn.LET(_xlpm.x,VLOOKUP(Table3[[#This Row],[Collector2]],'Drop-down_menus'!$F$2:$G$16,2,FALSE),IF(_xlpm.x=0,"",_xlpm.x))) | R8: =IF(Table3[[#This Row],[Collector3]]="","", _xlfn.LET(_xlpm.x,VLOOKUP(Table3[[#This Row],[Collector3]],'Drop-down_menus'!$F$2:$G$16,2,FALSE),IF(_xlpm.x=0,"",_xlpm.x))) | S8: =IF(Table3[[#This Row],[Collector4]]="","", _xlfn.LET(_xlpm.x,VLOOKUP(Table3[[#This Row],[Collector4]],'Drop-down_menus'!$F$2:$G$16,2,FALSE),IF(_xlpm.x=0,"",_xlpm.x))) | T8: 64°19,235 | U8: 62°55,418 | Y8: 20 | AC8: Leak
A9: Melchior Island, North Omega | B9: https://data.aad.gov.au/aadc/gaz/scar/display_name.cfm?gaz_id=110104 | C9: DIV_3 | D9: =_xlfn.TEXTBEFORE(Table3[[#This Row],[eventID]],"_") -> DIV | E9: 45334 | G9: 0.37638889 | H9: 0.40763889 | I9: 09:02-03:00/09:47-03:00 | J9: 2024-02-12 | K9: =H9-G9 -> 0.03125 | L9: Anthony Voisin | M9: Martin Dogniez | P9: =IF(Table3[[#This Row],[Collector1]]="","", _xlfn.LET(_xlpm.x,VLOOKUP(Table3[[#This Row],[Collector1]],'Drop-down_menus'!$F$2:$G$16,2,FALSE),IF(_xlpm.x=0,"",_xlpm.x))) -> https://orcid.org/0000-0003-3696-4445 | Q9: =IF(Table3[[#This Row],[Collector2]]="","", _xlfn.LET(_xlpm.x,VLOOKUP(Table3[[#This Row],[Collector2]],'Drop-down_menus'!$F$2:$G$16,2,FALSE),IF(_xlpm.x=0,"",_xlpm.x))) -> https://orcid.org/0000-0002-9708-1761 | R9: =IF(Table3[[#This Row],[Collector3]]="","", _xlfn.LET(_xlpm.x,VLOOKUP(Table3[[#This Row],[Collector3]],'Drop-down_menus'!$F$2:$G$16,2,FALSE),IF(_xlpm.x=0,"",_xlpm.x))) | S9: =IF(Table3[[#This Row],[Collector4]]="","", _xlfn.LET(_xlpm.x,VLOOKUP(Table3[[#This Row],[Collector4]],'Drop-down_menus'!$F$2:$G$16,2,FALSE),IF(_xlpm.x=0,"",_xlpm.x))) | T9: 64°19,235 | U9: 62°55,418 | Y9: 20 | AA9: 301 | AC9: Trophic Quadrats
A10: Melchior Island, North Omega | B10: https://data.aad.gov.au/aadc/gaz/scar/display_name.cfm?gaz_id=110104 | C10: DIV_4 | D10: =_xlfn.TEXTBEFORE(Table3[[#This Row],[eventID]],"_") -> DIV | E10: 45334 | G10: 0.44236111 | H10: 0.47847222 | I10: 10:37-03:00/11:29-03:00 | J10: 2024-02-12 | K10: =H10-G10 -> 0.036111111 | L10: Lea Katz | M10: Lucas Terrana | N10: Camille Moreau | P10: =IF(Table3[[#This Row],[Collector1]]="","", _xlfn.LET(_xlpm.x,VLOOKUP(Table3[[#This Row],[Collector1]],'Drop-down_menus'!$F$2:$G$16,2,FALSE),IF(_xlpm.x=0,"",_xlpm.x))) -> https://orcid.org/0000-0001-5748-602X | Q10: =IF(Table3[[#This Row],[Collector2]]="","", _xlfn.LET(_xlpm.x,VLOOKUP(Table3[[#This Row],[Collector2]],'Drop-down_menus'!$F$2:$G$16,2,FALSE),IF(_xlpm.x=0,"",_xlpm.x))) -> https://orcid.org/0000-0001-5767-3220 | R10: =IF(Table3[[#This Row],[Collector3]]="","", _xlfn.LET(_xlpm.x,VLOOKUP(Table3[[#This Row],[Collector3]],'Drop-down_menus'!$F$2:$G$16,2,FALSE),IF(_xlpm.x=0,"",_xlpm.x))) -> https://orcid.org/0000-0002-0981-7442 | S10: =IF(Table3[[#This Row],[Collector4]]="","", _xlfn.LET(_xlpm.x,VLOOKUP(Table3[[#This Row],[Collector4]],'Drop-down_menus'!$F$2:$G$16,2,FALSE),IF(_xlpm.x=0,"",_xlpm.x))) | T10: 64°19,235 | U10: 62°55,418 | Y10: 22 | AA10: 140 | AB10: 150 | AC10: Morphotype collection and documentation
A11: Melchior Island, North Omega | B11: https://data.aad.gov.au/aadc/gaz/scar/display_name.cfm?gaz_id=110104 | C11: NIS_2 | D11: =_xlfn.TEXTBEFORE(Table3[[#This Row],[eventID]],"_") -> NIS | E11: 45334 | G11: 0.41666667 | H11: 0.43055556 | I11: 10:00-03:00/10:20-03:00 | J11: 2024-02-12 | K11: =H11-G11 -> 0.013888889 | L11: Axelle Brusselman | M11: Manon Bayat | P11: =IF(Table3[[#This Row],[Collector1]]="","", _xlfn.LET(_xlpm.x,VLOOKUP(Table3[[#This Row],[Collector1]],'Drop-down_menus'!$F$2:$G$16,2,FALSE),IF(_xlpm.x=0,"",_xlpm.x))) -> https://orcid.org/0009-0002-6669-2911 | Q11: =IF(Table3[[#This Row],[Collector2]]="","", _xlfn.LET(_xlpm.x,VLOOKUP(Table3[[#This Row],[Collector2]],'Drop-down_menus'!$F$2:$G$16,2,FALSE),IF(_xlpm.x=0,"",_xlpm.x))) | R11: =IF(Table3[[#This Row],[Collector3]]="","", _xlfn.LET(_xlpm.x,VLOOKUP(Table3[[#This Row],[Collector3]],'Drop-down_menus'!$F$2:$G$16,2,FALSE),IF(_xlpm.x=0,"",_xlpm.x))) | S11: =IF(Table3[[#This Row],[Collector4]]="","", _xlfn.LET(_xlpm.x,VLOOKUP(Table3[[#This Row],[Collector4]],'Drop-down_menus'!$F$2:$G$16,2,FALSE),IF(_xlpm.x=0,"",_xlpm.x))) | T11: 64°19,235 | U11: 62°55,418 | X11: 0 | Y11: 20 | AA11: 171 | AB11: 182
A12: Melchior Island, North Omega | B12: https://data.aad.gov.au/aadc/gaz/scar/display_name.cfm?gaz_id=110104 | C12: NIS_3 | D12: =_xlfn.TEXTBEFORE(Table3[[#This Row],[eventID]],"_") -> NIS | E12: 45334 | G12: 0.61458333 | H12: 0.61805556 | I12: 14:45-03:00/14:50-03:00 | J12: 2024-02-12 | K12: =H12-G12 -> 0.0034722222 | L12: Axelle Brusselman | M12: Manon Bayat | P12: =IF(Table3[[#This Row],[Collector1]]="","", _xlfn.LET(_xlpm.x,VLOOKUP(Table3[[#This Row],[Collector1]],'Drop-down_menus'!$F$2:$G$16,2,FALSE),IF(_xlpm.x=0,"",_xlpm.x))) -> https://orcid.org/0009-0002-6669-2911 | Q12: =IF(Table3[[#This Row],[Collector2]]="","", _xlfn.LET(_xlpm.x,VLOOKUP(Table3[[#This Row],[Collector2]],'Drop-down_menus'!$F$2:$G$16,2,FALSE),IF(_xlpm.x=0,"",_xlpm.x))) | R12: =IF(Table3[[#This Row],[Collector3]]="","", _xlfn.LET(_xlpm.x,VLOOKUP(Table3[[#This Row],[Collector3]],'Drop-down_menus'!$F$2:$G$16,2,FALSE),IF(_xlpm.x=0,"",_xlpm.x))) | S12: =IF(Table3[[#This Row],[Collector4]]="","", _xlfn.LET(_xlpm.x,VLOOKUP(Table3[[#This Row],[Collector4]],'Drop-down_menus'!$F$2:$G$16,2,FALSE),IF(_xlpm.x=0,"",_xlpm.x))) | Y12: 0 | AA12: 183 | AB12: 188 | AD12: 64.315098 | AE12: 62.930713
A13: Melchior Island, North Omega | B13: https://data.aad.gov.au/aadc/gaz/scar/display_name.cfm?gaz_id=110104 | C13: NIS_4 | D13: =_xlfn.TEXTBEFORE(Table3[[#This Row],[eventID]],"_") -> NIS | E13: 45334 | G13: 0.63125 | H13: 0.63402778 | I13: 15:09-03:00/15:13-03:00 | J13: 2024-02-12 | K13: =H13-G13 -> 0.0027777778 | L13: Axelle Brusselman | M13: Manon Bayat | P13: =IF(Table3[[#This Row],[Collector1]]="","", _xlfn.LET(_xlpm.x,VLOOKUP(Table3[[#This Row],[Collector1]],'Drop-down_menus'!$F$2:$G$16,2,FALSE),IF(_xlpm.x=0,"",_xlpm.x))) -> https://orcid.org/0009-0002-6669-2911 | Q13: =IF(Table3[[#This Row],[Collector2]]="","", _xlfn.LET(_xlpm.x,VLOOKUP(Table3[[#This Row],[Collector2]],'Drop-down_menus'!$F$2:$G$16,2,FALSE),IF(_xlpm.x=0,"",_xlpm.x))) | R13: =IF(Table3[[#This Row],[Collector3]]="","", _xlfn.LET(_xlpm.x,VLOOKUP(Table3[[#This Row],[Collector3]],'Drop-down_menus'!$F$2:$G$16,2,FALSE),IF(_xlpm.x=0,"",_xlpm.x))) | S13: =IF(Table3[[#This Row],[Collector4]]="","", _xlfn.LET(_xlpm.x,VLOOKUP(Table3[[#This Row],[Collector4]],'Drop-down_menus'!$F$2:$G$16,2,FALSE),IF(_xlpm.x=0,"",_xlpm.x))) | Y13: 0 | AA13: 189 | AB13: 194 | AD13: 64.307023 | AE13: 62.947417
A14: Melchior Island, North Omega | B14: https://data.aad.gov.au/aadc/gaz/scar/display_name.cfm?gaz_id=110104 | C14: NIS_5 | D14: =_xlfn.TEXTBEFORE(Table3[[#This Row],[eventID]],"_") -> NIS | E14: 45334 | G14: 0.63819444 | H14: 0.64166667 | I14: 15:19-03:00/15:24-03:00 | J14: 2024-02-12 | K14: =H14-G14 -> 0.0034722222 | L14: Axelle Brusselman | M14: Manon Bayat | P14: =IF(Table3[[#This Row],[Collector1]]="","", _xlfn.LET(_xlpm.x,VLOOKUP(Table3[[#This Row],[Collector1]],'Drop-down_menus'!$F$2:$G$16,2,FALSE),IF(_xlpm.x=0,"",_xlpm.x))) -> https://orcid.org/0009-0002-6669-2911 | Q14: =IF(Table3[[#This Row],[Collector2]]="","", _xlfn.LET(_xlpm.x,VLOOKUP(Table3[[#This Row],[Collector2]],'Drop-down_menus'!$F$2:$G$16,2,FALSE),IF(_xlpm.x=0,"",_xlpm.x))) | R14: =IF(Table3[[#This Row],[Collector3]]="","", _xlfn.LET(_xlpm.x,VLOOKUP(Table3[[#This Row],[Collector3]],'Drop-down_menus'!$F$2:$G$16,2,FALSE),IF(_xlpm.x=0,"",_xlpm.x))) | S14: =IF(Table3[[#This Row],[Collector4]]="","", _xlfn.LET(_xlpm.x,VLOOKUP(Table3[[#This Row],[Collector4]],'Drop-down_menus'!$F$2:$G$16,2,FALSE),IF(_xlpm.x=0,"",_xlpm.x))) | Y14: 0 | AA14: 195 | AB14: 200 | AD14: 64.308496 | AE14: 62.94315
A15: Melchior Island, North Omega | B15: https://data.aad.gov.au/aadc/gaz/scar/display_name.cfm?gaz_id=110104 | C15: NIS_6 | D15: =_xlfn.TEXTBEFORE(Table3[[#This Row],[eventID]],"_") -> NIS | E15: 45334 | G15: 0.64583333 | H15: 0.64930556 | I15: 15:30-03:00/15:35-03:00 | J15: 2024-02-12 | K15: =H15-G15 -> 0.0034722222 | L15: Axelle Brusselman | M15: Manon Bayat | P15: =IF(Table3[[#This Row],[Collector1]]="","", _xlfn.LET(_xlpm.x,VLOOKUP(Table3[[#This Row],[Collector1]],'Drop-down_menus'!$F$2:$G$16,2,FALSE),IF(_xlpm.x=0,"",_xlpm.x))) -> https://orcid.org/0009-0002-6669-2911 | Q15: =IF(Table3[[#This Row],[Collector2]]="","", _xlfn.LET(_xlpm.x,VLOOKUP(Table3[[#This Row],[Collector2]],'Drop-down_menus'!$F$2:$G$16,2,FALSE),IF(_xlpm.x=0,"",_xlpm.x))) | R15: =IF(Table3[[#This Row],[Collector3]]="","", _xlfn.LET(_xlpm.x,VLOOKUP(Table3[[#This Row],[Collector3]],'Drop-down_menus'!$F$2:$G$16,2,FALSE),IF(_xlpm.x=0,"",_xlpm.x))) | S15: =IF(Table3[[#This Row],[Collector4]]="","", _xlfn.LET(_xlpm.x,VLOOKUP(Table3[[#This Row],[Collector4]],'Drop-down_menus'!$F$2:$G$16,2,FALSE),IF(_xlpm.x=0,"",_xlpm.x))) | Y15: 0 | AA15: 201 | AB15: 206 | AD15: 64.317163 | AE15: 62.927629
A16: Melchior Island, North Omega | B16: https://data.aad.gov.au/aadc/gaz/scar/display_name.cfm?gaz_id=110104 | C16: NIS_7 | D16: =_xlfn.TEXTBEFORE(Table3[[#This Row],[eventID]],"_") -> NIS | E16: 45334 | G16: 0.65208333 | H16: 0.65555556 | I16: 15:39-03:00/15:44-03:00 | J16: 2024-02-12 | K16: =H16-G16 -> 0.0034722222 | L16: Axelle Brusselman | M16: Manon Bayat | P16: =IF(Table3[[#This Row],[Collector1]]="","", _xlfn.LET(_xlpm.x,VLOOKUP(Table3[[#This Row],[Collector1]],'Drop-down_menus'!$F$2:$G$16,2,FALSE),IF(_xlpm.x=0,"",_xlpm.x))) -> https://orcid.org/0009-0002-6669-2911 | Q16: =IF(Table3[[#This Row],[Collector2]]="","", _xlfn.LET(_xlpm.x,VLOOKUP(Table3[[#This Row],[Collector2]],'Drop-down_menus'!$F$2:$G$16,2,FALSE),IF(_xlpm.x=0,"",_xlpm.x))) | R16: =IF(Table3[[#This Row],[Collector3]]="","", _xlfn.LET(_xlpm.x,VLOOKUP(Table3[[#This Row],[Collector3]],'Drop-down_menus'!$F$2:$G$16,2,FALSE),IF(_xlpm.x=0,"",_xlpm.x))) | S16: =IF(Table3[[#This Row],[Collector4]]="","", _xlfn.LET(_xlpm.x,VLOOKUP(Table3[[#This Row],[Collector4]],'Drop-down_menus'!$F$2:$G$16,2,FALSE),IF(_xlpm.x=0,"",_xlpm.x))) | Y16: 0 | AA16: 207 | AB16: 212 | AD16: 64.318697 | AE16: 62.926535
A17: Melchior Island, North Omega | B17: https://data.aad.gov.au/aadc/gaz/scar/display_name.cfm?gaz_id=110104 | C17: NIS_8 | D17: =_xlfn.TEXTBEFORE(Table3[[#This Row],[eventID]],"_") -> NIS | E17: 45334 | G17: 0.65833333 | H17: 0.66180556 | I17: 15:48-03:00/15:53-03:00 | J17: 2024-02-12 | K17: =H17-G17 -> 0.0034722222 | L17: Axelle Brusselman | M17: Manon Bayat | P17: =IF(Table3[[#This Row],[Collector1]]="","", _xlfn.LET(_xlpm.x,VLOOKUP(Table3[[#This Row],[Collector1]],'Drop-down_menus'!$F$2:$G$16,2,FALSE),IF(_xlpm.x=0,"",_xlpm.x))) -> https://orcid.org/0009-0002-6669-2911 | Q17: =IF(Table3[[#This Row],[Collector2]]="","", _xlfn.LET(_xlpm.x,VLOOKUP(Table3[[#This Row],[Collector2]],'Drop-down_menus'!$F$2:$G$16,2,FALSE),IF(_xlpm.x=0,"",_xlpm.x))) | R17: =IF(Table3[[#This Row],[Collector3]]="","", _xlfn.LET(_xlpm.x,VLOOKUP(Table3[[#This Row],[Collector3]],'Drop-down_menus'!$F$2:$G$16,2,FALSE),IF(_xlpm.x=0,"",_xlpm.x))) | S17: =IF(Table3[[#This Row],[Collector4]]="","", _xlfn.LET(_xlpm.x,VLOOKUP(Table3[[#This Row],[Collector4]],'Drop-down_menus'!$F$2:$G$16,2,FALSE),IF(_xlpm.x=0,"",_xlpm.x))) | Y17: 0 | AA17: 213 | AB17: 218 | AD17: 64.319872 | AE17: 62.92531
A18: Melchior Island, North Omega | B18: https://data.aad.gov.au/aadc/gaz/scar/display_name.cfm?gaz_id=110104 | C18: NIS_9 | D18: =_xlfn.TEXTBEFORE(Table3[[#This Row],[eventID]],"_") -> NIS | E18: 45334 | G18: 0.66458333 | H18: 0.66805556 | I18: 15:57-03:00/16:02-03:00 | J18: 2024-02-12 | K18: =H18-G18 -> 0.0034722222 | L18: Axelle Brusselman | M18: Manon Bayat | P18: =IF(Table3[[#This Row],[Collector1]]="","", _xlfn.LET(_xlpm.x,VLOOKUP(Table3[[#This Row],[Collector1]],'Drop-down_menus'!$F$2:$G$16,2,FALSE),IF(_xlpm.x=0,"",_xlpm.x))) -> https://orcid.org/0009-0002-6669-2911 | Q18: =IF(Table3[[#This Row],[Collector2]]="","", _xlfn.LET(_xlpm.x,VLOOKUP(Table3[[#This Row],[Collector2]],'Drop-down_menus'!$F$2:$G$16,2,FALSE),IF(_xlpm.x=0,"",_xlpm.x))) | R18: =IF(Table3[[#This Row],[Collector3]]="","", _xlfn.LET(_xlpm.x,VLOOKUP(Table3[[#This Row],[Collector3]],'Drop-down_menus'!$F$2:$G$16,2,FALSE),IF(_xlpm.x=0,"",_xlpm.x))) | S18: =IF(Table3[[#This Row],[Collector4]]="","", _xlfn.LET(_xlpm.x,VLOOKUP(Table3[[#This Row],[Collector4]],'Drop-down_menus'!$F$2:$G$16,2,FALSE),IF(_xlpm.x=0,"",_xlpm.x))) | Y18: 0 | AA18: 219 | AB18: 224 | AD18: 64.320347 | AE18: 62.923212
A19: Melchior Island, North Omega | B19: https://data.aad.gov.au/aadc/gaz/scar/display_name.cfm?gaz_id=110104 | C19: NIS_10 | D19: =_xlfn.TEXTBEFORE(Table3[[#This Row],[eventID]],"_") -> NIS | E19: 45334 | G19: 0.67708333 | H19: 0.68055556 | I19: 16:15-03:00/16:20-03:00 | J19: 2024-02-12 | K19: =H19-G19 -> 0.0034722222 | L19: Axelle Brusselman | M19: Manon Bayat | P19: =IF(Table3[[#This Row],[Collector1]]="","", _xlfn.LET(_xlpm.x,VLOOKUP(Table3[[#This Row],[Collector1]],'Drop-down_menus'!$F$2:$G$16,2,FALSE),IF(_xlpm.x=0,"",_xlpm.x))) -> https://orcid.org/0009-0002-6669-2911 | Q19: =IF(Table3[[#This Row],[Collector2]]="","", _xlfn.LET(_xlpm.x,VLOOKUP(Table3[[#This Row],[Collector2]],'Drop-down_menus'!$F$2:$G$16,2,FALSE),IF(_xlpm.x=0,"",_xlpm.x))) | R19: =IF(Table3[[#This Row],[Collector3]]="","", _xlfn.LET(_xlpm.x,VLOOKUP(Table3[[#This Row],[Collector3]],'Drop-down_menus'!$F$2:$G$16,2,FALSE),IF(_xlpm.x=0,"",_xlpm.x))) | S19: =IF(Table3[[#This Row],[Collector4]]="","", _xlfn.LET(_xlpm.x,VLOOKUP(Table3[[#This Row],[Collector4]],'Drop-down_menus'!$F$2:$G$16,2,FALSE),IF(_xlpm.x=0,"",_xlpm.x))) | Y19: 0 | AA19: 225 | AB19: 230 | AC19: Second CH4/N2O exploded | AD19: 64.320825 | AE19: 62.900296
A20: Melchior Island, North Omega | B20: https://data.aad.gov.au/aadc/gaz/scar/display_name.cfm?gaz_id=110104 | C20: NIS_11 | D20: =_xlfn.TEXTBEFORE(Table3[[#This Row],[eventID]],"_") -> NIS | E20: 45334 | G20: 0.68472222 | H20: 0.68819444 | I20: 16:26-03:00/16:31-03:00 | J20: 2024-02-12 | K20: =H20-G20 -> 0.0034722222 | L20: Axelle Brusselman | M20: Manon Bayat | P20: =IF(Table3[[#This Row],[Collector1]]="","", _xlfn.LET(_xlpm.x,VLOOKUP(Table3[[#This Row],[Collector1]],'Drop-down_menus'!$F$2:$G$16,2,FALSE),IF(_xlpm.x=0,"",_xlpm.x))) -> https://orcid.org/0009-0002-6669-2911 | Q20: =IF(Table3[[#This Row],[Collector2]]="","", _xlfn.LET(_xlpm.x,VLOOKUP(Table3[[#This Row],[Collector2]],'Drop-down_menus'!$F$2:$G$16,2,FALSE),IF(_xlpm.x=0,"",_xlpm.x))) | R20: =IF(Table3[[#This Row],[Collector3]]="","", _xlfn.LET(_xlpm.x,VLOOKUP(Table3[[#This Row],[Collector3]],'Drop-down_menus'!$F$2:$G$16,2,FALSE),IF(_xlpm.x=0,"",_xlpm.x))) | S20: =IF(Table3[[#This Row],[Collector4]]="","", _xlfn.LET(_xlpm.x,VLOOKUP(Table3[[#This Row],[Collector4]],'Drop-down_menus'!$F$2:$G$16,2,FALSE),IF(_xlpm.x=0,"",_xlpm.x))) | Y20: 0 | AA20: 231 | AB20: 236 | AD20: 64.319152 | AE20: 62.909623
A21: Melchior Island, North Omega | B21: https://data.aad.gov.au/aadc/gaz/scar/display_name.cfm?gaz_id=110104 | C21: NIS_12 | D21: =_xlfn.TEXTBEFORE(Table3[[#This Row],[eventID]],"_") -> NIS | E21: 45334 | G21: 0.69027778 | H21: 0.69375 | I21: 16:34-03:00/16:39-03:00 | J21: 2024-02-12 | K21: =H21-G21 -> 0.0034722222 | L21: Axelle Brusselman | M21: Manon Bayat | P21: =IF(Table3[[#This Row],[Collector1]]="","", _xlfn.LET(_xlpm.x,VLOOKUP(Table3[[#This Row],[Collector1]],'Drop-down_menus'!$F$2:$G$16,2,FALSE),IF(_xlpm.x=0,"",_xlpm.x))) -> https://orcid.org/0009-0002-6669-2911 | Q21: =IF(Table3[[#This Row],[Collector2]]="","", _xlfn.LET(_xlpm.x,VLOOKUP(Table3[[#This Row],[Collector2]],'Drop-down_menus'!$F$2:$G$16,2,FALSE),IF(_xlpm.x=0,"",_xlpm.x))) | R21: =IF(Table3[[#This Row],[Collector3]]="","", _xlfn.LET(_xlpm.x,VLOOKUP(Table3[[#This Row],[Collector3]],'Drop-down_menus'!$F$2:$G$16,2,FALSE),IF(_xlpm.x=0,"",_xlpm.x))) | S21: =IF(Table3[[#This Row],[Collector4]]="","", _xlfn.LET(_xlpm.x,VLOOKUP(Table3[[#This Row],[Collector4]],'Drop-down_menus'!$F$2:$G$16,2,FALSE),IF(_xlpm.x=0,"",_xlpm.x))) | Y21: 0 | AA21: 237 | AB21: 242 | AC21: 6-7 m from glacier | AD21: 64.31974 | AE21: 62.917007
A22: Melchior Island, North Omega | B22: https://data.aad.gov.au/aadc/gaz/scar/display_name.cfm?gaz_id=110104 | C22: NIS_13 | D22: =_xlfn.TEXTBEFORE(Table3[[#This Row],[eventID]],"_") -> NIS | E22: 45334 | G22: 0.7 | H22: 0.70347222 | I22: 16:48-03:00/16:53-03:00 | J22: 2024-02-12 | K22: =H22-G22 -> 0.0034722222 | L22: Axelle Brusselman | M22: Manon Bayat | P22: =IF(Table3[[#This Row],[Collector1]]="","", _xlfn.LET(_xlpm.x,VLOOKUP(Table3[[#This Row],[Collector1]],'Drop-down_menus'!$F$2:$G$16,2,FALSE),IF(_xlpm.x=0,"",_xlpm.x))) -> https://orcid.org/0009-0002-6669-2911 | Q22: =IF(Table3[[#This Row],[Collector2]]="","", _xlfn.LET(_xlpm.x,VLOOKUP(Table3[[#This Row],[Collector2]],'Drop-down_menus'!$F$2:$G$16,2,FALSE),IF(_xlpm.x=0,"",_xlpm.x))) | R22: =IF(Table3[[#This Row],[Collector3]]="","", _xlfn.LET(_xlpm.x,VLOOKUP(Table3[[#This Row],[Collector3]],'Drop-down_menus'!$F$2:$G$16,2,FALSE),IF(_xlpm.x=0,"",_xlpm.x))) | S22: =IF(Table3[[#This Row],[Collector4]]="","", _xlfn.LET(_xlpm.x,VLOOKUP(Table3[[#This Row],[Collector4]],'Drop-down_menus'!$F$2:$G$16,2,FALSE),IF(_xlpm.x=0,"",_xlpm.x))) | Y22: 0 | AA22: 243 | AB22: 248 | AC22: Run-off | AD22: 64.316989 | AE22: 62.914304
A23: Melchior Island, North Omega | B23: https://data.aad.gov.au/aadc/gaz/scar/display_name.cfm?gaz_id=110104 | C23: NIS_14 | D23: =_xlfn.TEXTBEFORE(Table3[[#This Row],[eventID]],"_") -> NIS | E23: 45334 | G23: 0.70763889 | H23: 0.71111111 | I23: 16:59-03:00/17:04-03:00 | J23: 2024-02-12 | K23: =H23-G23 -> 0.0034722222 | L23: Axelle Brusselman | M23: Manon Bayat | P23: =IF(Table3[[#This Row],[Collector1]]="","", _xlfn.LET(_xlpm.x,VLOOKUP(Table3[[#This Row],[Collector1]],'Drop-down_menus'!$F$2:$G$16,2,FALSE),IF(_xlpm.x=0,"",_xlpm.x))) -> https://orcid.org/0009-0002-6669-2911 | Q23: =IF(Table3[[#This Row],[Collector2]]="","", _xlfn.LET(_xlpm.x,VLOOKUP(Table3[[#This Row],[Collector2]],'Drop-down_menus'!$F$2:$G$16,2,FALSE),IF(_xlpm.x=0,"",_xlpm.x))) | R23: =IF(Table3[[#This Row],[Collector3]]="","", _xlfn.LET(_xlpm.x,VLOOKUP(Table3[[#This Row],[Collector3]],'Drop-down_menus'!$F$2:$G$16,2,FALSE),IF(_xlpm.x=0,"",_xlpm.x))) | S23: =IF(Table3[[#This Row],[Collector4]]="","", _xlfn.LET(_xlpm.x,VLOOKUP(Table3[[#This Row],[Collector4]],'Drop-down_menus'!$F$2:$G$16,2,FALSE),IF(_xlpm.x=0,"",_xlpm.x))) | Y23: 0 | AA23: 249 | AB23: 254 | AC23: Run-off | AD23: 64.319271 | AE23: 62.917854
A24: Melchior Island, North Omega | B24: https://data.aad.gov.au/aadc/gaz/scar/display_name.cfm?gaz_id=110104 | C24: NIS_15 | D24: =_xlfn.TEXTBEFORE(Table3[[#This Row],[eventID]],"_") -> NIS | E24: 45334 | G24: 0.71388889 | H24: 0.71736111 | I24: 17:08-03:00/17:13-03:00 | J24: 2024-02-12 | K24: =H24-G24 -> 0.0034722222 | L24: Axelle Brusselman | M24: Manon Bayat | P24: =IF(Table3[[#This Row],[Collector1]]="","", _xlfn.LET(_xlpm.x,VLOOKUP(Table3[[#This Row],[Collector1]],'Drop-down_menus'!$F$2:$G$16,2,FALSE),IF(_xlpm.x=0,"",_xlpm.x))) -> https://orcid.org/0009-0002-6669-2911 | Q24: =IF(Table3[[#This Row],[Collector2]]="","", _xlfn.LET(_xlpm.x,VLOOKUP(Table3[[#This Row],[Collector2]],'Drop-down_menus'!$F$2:$G$16,2,FALSE),IF(_xlpm.x=0,"",_xlpm.x))) | R24: =IF(Table3[[#This Row],[Collector3]]="","", _xlfn.LET(_xlpm.x,VLOOKUP(Table3[[#This Row],[Collector3]],'Drop-down_menus'!$F$2:$G$16,2,FALSE),IF(_xlpm.x=0,"",_xlpm.x))) | S24: =IF(Table3[[#This Row],[Collector4]]="","", _xlfn.LET(_xlpm.x,VLOOKUP(Table3[[#This Row],[Collector4]],'Drop-down_menus'!$F$2:$G$16,2,FALSE),IF(_xlpm.x=0,"",_xlpm.x))) | Y24: 0 | AA24: 255 | AB24: 260 | AC24: No Run-off | AD24: 64.32025 | AE24: 62.915516
A25: Melchior Island, North Omega | B25: https://data.aad.gov.au/aadc/gaz/scar/display_name.cfm?gaz_id=110104 | C25: NIS_16 | D25: =_xlfn.TEXTBEFORE(Table3[[#This Row],[eventID]],"_") -> NIS | E25: 45334 | G25: 0.72013889 | H25: 0.72361111 | I25: 17:17-03:00/17:22-03:00 | J25: 2024-02-12 | K25: =H25-G25 -> 0.0034722222 | L25: Axelle Brusselman | M25: Manon Bayat | P25: =IF(Table3[[#This Row],[Collector1]]="","", _xlfn.LET(_xlpm.x,VLOOKUP(Table3[[#This Row],[Collector1]],'Drop-down_menus'!$F$2:$G$16,2,FALSE),IF(_xlpm.x=0,"",_xlpm.x))) -> https://orcid.org/0009-0002-6669-2911 | Q25: =IF(Table3[[#This Row],[Collector2]]="","", _xlfn.LET(_xlpm.x,VLOOKUP(Table3[[#This Row],[Collector2]],'Drop-down_menus'!$F$2:$G$16,2,FALSE),IF(_xlpm.x=0,"",_xlpm.x))) | R25: =IF(Table3[[#This Row],[Collector3]]="","", _xlfn.LET(_xlpm.x,VLOOKUP(Table3[[#This Row],[Collector3]],'Drop-down_menus'!$F$2:$G$16,2,FALSE),IF(_xlpm.x=0,"",_xlpm.x))) | S25: =IF(Table3[[#This Row],[Collector4]]="","", _xlfn.LET(_xlpm.x,VLOOKUP(Table3[[#This Row],[Collector4]],'Drop-down_menus'!$F$2:$G$16,2,FALSE),IF(_xlpm.x=0,"",_xlpm.x))) | Y25: 0 | AA25: 261 | AB25: 266 | AC25: No Run-off | AD25: 64.320581 | AE25: 62.918766
A26: Melchior Island, North Omega | B26: https://data.aad.gov.au/aadc/gaz/scar/display_name.cfm?gaz_id=110104 | C26: ROV_2 | D26: =_xlfn.TEXTBEFORE(Table3[[#This Row],[eventID]],"_") -> ROV | E26: 45334 | G26: 0.57361111 | H26: 0.58125 | I26: 13:46-03:00/13:57-03:00 | J26: 2024-02-12 | K26: =H26-G26 -> 0.0076388889 | L26: Lea Katz | M26: Henri Robert | P26: =IF(Table3[[#This Row],[Collector1]]="","", _xlfn.LET(_xlpm.x,VLOOKUP(Table3[[#This Row],[Collector1]],'Drop-down_menus'!$F$2:$G$16,2,FALSE),IF(_xlpm.x=0,"",_xlpm.x))) -> https://orcid.org/0000-0001-5748-602X | Q26: =IF(Table3[[#This Row],[Collector2]]="","", _xlfn.LET(_xlpm.x,VLOOKUP(Table3[[#This Row],[Collector2]],'Drop-down_menus'!$F$2:$G$16,2,FALSE),IF(_xlpm.x=0,"",_xlpm.x))) | R26: =IF(Table3[[#This Row],[Collector3]]="","", _xlfn.LET(_xlpm.x,VLOOKUP(Table3[[#This Row],[Collector3]],'Drop-down_menus'!$F$2:$G$16,2,FALSE),IF(_xlpm.x=0,"",_xlpm.x))) | S26: =IF(Table3[[#This Row],[Collector4]]="","", _xlfn.LET(_xlpm.x,VLOOKUP(Table3[[#This Row],[Collector4]],'Drop-down_menus'!$F$2:$G$16,2,FALSE),IF(_xlpm.x=0,"",_xlpm.x))) | T26: 64°19,235 | U26: 62°55,418 | X26: 0 | Y26: 20
A27: Melchior Island, North Omega | B27: https://data.aad.gov.au/aadc/gaz/scar/display_name.cfm?gaz_id=110104 | C27: ROV_3 | D27: =_xlfn.TEXTBEFORE(Table3[[#This Row],[eventID]],"_") -> ROV | E27: 45334 | G27: 0.68541667 | H27: 0.69513889 | I27: 16:27-03:00/16:41-03:00 | J27: 2024-02-12 | K27: =H27-G27 -> 0.0097222222 | L27: Lea Katz | M27: Henri Robert | P27: =IF(Table3[[#This Row],[Collector1]]="","", _xlfn.LET(_xlpm.x,VLOOKUP(Table3[[#This Row],[Collector1]],'Drop-down_menus'!$F$2:$G$16,2,FALSE),IF(_xlpm.x=0,"",_xlpm.x))) -> https://orcid.org/0000-0001-5748-602X | Q27: =IF(Table3[[#This Row],[Collector2]]="","", _xlfn.LET(_xlpm.x,VLOOKUP(Table3[[#This Row],[Collector2]],'Drop-down_menus'!$F$2:$G$16,2,FALSE),IF(_xlpm.x=0,"",_xlpm.x))) | R27: =IF(Table3[[#This Row],[Collector3]]="","", _xlfn.LET(_xlpm.x,VLOOKUP(Table3[[#This Row],[Collector3]],'Drop-down_menus'!$F$2:$G$16,2,FALSE),IF(_xlpm.x=0,"",_xlpm.x))) | S27: =IF(Table3[[#This Row],[Collector4]]="","", _xlfn.LET(_xlpm.x,VLOOKUP(Table3[[#This Row],[Collector4]],'Drop-down_menus'!$F$2:$G$16,2,FALSE),IF(_xlpm.x=0,"",_xlpm.x))) | T27: 64°19,235 | U27: 62°55,418 | X27: 5 | Y27: 13
A28: Melchior Island, North Omega | B28: https://data.aad.gov.au/aadc/gaz/scar/display_name.cfm?gaz_id=110104 | C28: RD_1 | D28: =_xlfn.TEXTBEFORE(Table3[[#This Row],[eventID]],"_") -> RD | E28: 45334 | G28: 0.5625 | H28: 0.57638889 | I28: 13:30-03:00/13:50-03:00 | J28: 2024-02-12 | K28: =H28-G28 -> 0.013888889 | L28: Henri Robert | P28: =IF(Table3[[#This Row],[Collector1]]="","", _xlfn.LET(_xlpm.x,VLOOKUP(Table3[[#This Row],[Collector1]],'Drop-down_menus'!$F$2:$G$16,2,FALSE),IF(_xlpm.x=0,"",_xlpm.x))) | Q28: =IF(Table3[[#This Row],[Collector2]]="","", _xlfn.LET(_xlpm.x,VLOOKUP(Table3[[#This Row],[Collector2]],'Drop-down_menus'!$F$2:$G$16,2,FALSE),IF(_xlpm.x=0,"",_xlpm.x))) | R28: =IF(Table3[[#This Row],[Collector3]]="","", _xlfn.LET(_xlpm.x,VLOOKUP(Table3[[#This Row],[Collector3]],'Drop-down_menus'!$F$2:$G$16,2,FALSE),IF(_xlpm.x=0,"",_xlpm.x))) | S28: =IF(Table3[[#This Row],[Collector4]]="","", _xlfn.LET(_xlpm.x,VLOOKUP(Table3[[#This Row],[Collector4]],'Drop-down_menus'!$F$2:$G$16,2,FALSE),IF(_xlpm.x=0,"",_xlpm.x))) | T28: 64°19,242 | U28: 62°55,372 | V28: 64°19,199 | W28: 62°55,421 | X28: 5 | Y28: 20 | AA28: 152 | AB28: 170
A29: Melchior Island, North Omega | B29: https://data.aad.gov.au/aadc/gaz/scar/display_name.cfm?gaz_id=110104 | C29: DRM_1 | D29: =_xlfn.TEXTBEFORE(Table3[[#This Row],[eventID]],"_") -> DRM | E29: 45334 | G29: 0.38680556 | H29: 0.42847222 | I29: 09:17-03:00/10:17-03:00 | J29: 2024-02-12 | K29: =H29-G29 -> 0.041666667 | L29: Bruno Danis | P29: =IF(Table3[[#This Row],[Collector1]]="","", _xlfn.LET(_xlpm.x,VLOOKUP(Table3[[#This Row],[Collector1]],'Drop-down_menus'!$F$2:$G$16,2,FALSE),IF(_xlpm.x=0,"",_xlpm.x))) -> https://orcid.org/0000-0002-9037-7623 | Q29: =IF(Table3[[#This Row],[Collector2]]="","", _xlfn.LET(_xlpm.x,VLOOKUP(Table3[[#This Row],[Collector2]],'Drop-down_menus'!$F$2:$G$16,2,FALSE),IF(_xlpm.x=0,"",_xlpm.x))) | R29: =IF(Table3[[#This Row],[Collector3]]="","", _xlfn.LET(_xlpm.x,VLOOKUP(Table3[[#This Row],[Collector3]],'Drop-down_menus'!$F$2:$G$16,2,FALSE),IF(_xlpm.x=0,"",_xlpm.x))) | S29: =IF(Table3[[#This Row],[Collector4]]="","", _xlfn.LET(_xlpm.x,VLOOKUP(Table3[[#This Row],[Collector4]],'Drop-down_menus'!$F$2:$G$16,2,FALSE),IF(_xlpm.x=0,"",_xlpm.x))) | Z29: 40 | AC29: Flight Time: 45'
A30: Melchior Island, North Omega | B30: https://data.aad.gov.au/aadc/gaz/scar/display_name.cfm?gaz_id=110104 | C30: DIV_5 | D30: =_xlfn.TEXTBEFORE(Table3[[#This Row],[eventID]],"_") -> DIV | E30: 45335 | G30: 0.36944444 | H30: 0.40833333 | I30: 08:52-03:00/09:48-03:00 | J30: 2024-02-13 | K30: =H30-G30 -> 0.038888889 | L30: Martin Dogniez | M30: Anthony Voisin | P30: =IF(Table3[[#This Row],[Collector1]]="","", _xlfn.LET(_xlpm.x,VLOOKUP(Table3[[#This Row],[Collector1]],'Drop-down_menus'!$F$2:$G$16,2,FALSE),IF(_xlpm.x=0,"",_xlpm.x))) -> https://orcid.org/0000-0002-9708-1761 | Q30: =IF(Table3[[#This Row],[Collector2]]="","", _xlfn.LET(_xlpm.x,VLOOKUP(Table3[[#This Row],[Collector2]],'Drop-down_menus'!$F$2:$G$16,2,FALSE),IF(_xlpm.x=0,"",_xlpm.x))) -> https://orcid.org/0000-0003-3696-4445 | R30: =IF(Table3[[#This Row],[Collector3]]="","", _xlfn.LET(_xlpm.x,VLOOKUP(Table3[[#This Row],[Collector3]],'Drop-down_menus'!$F$2:$G$16,2,FALSE),IF(_xlpm.x=0,"",_xlpm.x))) | S30: =IF(Table3[[#This Row],[Collector4]]="","", _xlfn.LET(_xlpm.x,VLOOKUP(Table3[[#This Row],[Collector4]],'Drop-down_menus'!$F$2:$G$16,2,FALSE),IF(_xlpm.x=0,"",_xlpm.x))) | T30: 64°19,235 | U30: 62°55,418 | Y30: 21 | AA30: 543 | AC30: Trophic Transects
A31: Melchior Island, North Omega | B31: https://data.aad.gov.au/aadc/gaz/scar/display_name.cfm?gaz_id=110104 | C31: RD_2 | D31: =_xlfn.TEXTBEFORE(Table3[[#This Row],[eventID]],"_") -> RD | E31: 45335 | G31: 0.35416667 | H31: 0.36805556 | I31: 08:30-03:00/08:50-03:00 | J31: 2024-02-13 | K31: =H31-G31 -> 0.013888889 | L31: Henri Robert | P31: =IF(Table3[[#This Row],[Collector1]]="","", _xlfn.LET(_xlpm.x,VLOOKUP(Table3[[#This Row],[Collector1]],'Drop-down_menus'!$F$2:$G$16,2,FALSE),IF(_xlpm.x=0,"",_xlpm.x))) | Q31: =IF(Table3[[#This Row],[Collector2]]="","", _xlfn.LET(_xlpm.x,VLOOKUP(Table3[[#This Row],[Collector2]],'Drop-down_menus'!$F$2:$G$16,2,FALSE),IF(_xlpm.x=0,"",_xlpm.x))) | R31: =IF(Table3[[#This Row],[Collector3]]="","", _xlfn.LET(_xlpm.x,VLOOKUP(Table3[[#This Row],[Collector3]],'Drop-down_menus'!$F$2:$G$16,2,FALSE),IF(_xlpm.x=0,"",_xlpm.x))) | S31: =IF(Table3[[#This Row],[Collector4]]="","", _xlfn.LET(_xlpm.x,VLOOKUP(Table3[[#This Row],[Collector4]],'Drop-down_menus'!$F$2:$G$16,2,FALSE),IF(_xlpm.x=0,"",_xlpm.x))) | T31: 64°19,192 | U31: 62°55,034 | V31: 64°19,237 | W31: 62°55,062 | X31: 8 | Y31: 22 | AA31: 449 | AB31: 462
A32: Melchior Island, North Omega | B32: https://data.aad.gov.au/aadc/gaz/scar/display_name.cfm?gaz_id=110104 | C32: DIV_6 | D32: =_xlfn.TEXTBEFORE(Table3[[#This Row],[eventID]],"_") -> DIV | E32: 45335 | G32: 0.37152778 | H32: 0.40972222 | I32: 08:55-03:00/09:50-03:00 | J32: 2024-02-13 | K32: =H32-G32 -> 0.038194444 | L32: Camille Moreau | M32: Lucas Terrana | P32: =IF(Table3[[#This Row],[Collector1]]="","", _xlfn.LET(_xlpm.x,VLOOKUP(Table3[[#This Row],[Collector1]],'Drop-down_menus'!$F$2:$G$16,2,FALSE),IF(_xlpm.x=0,"",_xlpm.x))) -> https://orcid.org/0000-0002-0981-7442 | Q32: =IF(Table3[[#This Row],[Collector2]]="","", _xlfn.LET(_xlpm.x,VLOOKUP(Table3[[#This Row],[Collector2]],'Drop-down_menus'!$F$2:$G$16,2,FALSE),IF(_xlpm.x=0,"",_xlpm.x))) -> https://orcid.org/0000-0001-5767-3220 | R32: =IF(Table3[[#This Row],[Collector3]]="","", _xlfn.LET(_xlpm.x,VLOOKUP(Table3[[#This Row],[Collector3]],'Drop-down_menus'!$F$2:$G$16,2,FALSE),IF(_xlpm.x=0,"",_xlpm.x))) | S32: =IF(Table3[[#This Row],[Collector4]]="","", _xlfn.LET(_xlpm.x,VLOOKUP(Table3[[#This Row],[Collector4]],'Drop-down_menus'!$F$2:$G$16,2,FALSE),IF(_xlpm.x=0,"",_xlpm.x))) | T32: 64°19,235 | U32: 62°55,418 | Y32: 23 | AA32: 448 | AB32: 542 | AC32: Careful: samples 448, 541, 542. Video transects, ROV testing for Leaks
A33: Melchior Island, North Omega | B33: https://data.aad.gov.au/aadc/gaz/scar/display_name.cfm?gaz_id=110104 | C33: ROV_4 | D33: =_xlfn.TEXTBEFORE(Table3[[#This Row],[eventID]],"_") -> ROV | E33: 45335 | G33: 0.55486111 | H33: 0.56666667 | I33: 13:19-03:00/13:36-03:00 | J33: 2024-02-13 | K33: =H33-G33 -> 0.011805556 | L33: Lea Katz | M33: Henri Robert | P33: =IF(Table3[[#This Row],[Collector1]]="","", _xlfn.LET(_xlpm.x,VLOOKUP(Table3[[#This Row],[Collector1]],'Drop-down_menus'!$F$2:$G$16,2,FALSE),IF(_xlpm.x=0,"",_xlpm.x))) -> https://orcid.org/0000-0001-5748-602X | Q33: =IF(Table3[[#This Row],[Collector2]]="","", _xlfn.LET(_xlpm.x,VLOOKUP(Table3[[#This Row],[Collector2]],'Drop-down_menus'!$F$2:$G$16,2,FALSE),IF(_xlpm.x=0,"",_xlpm.x))) | R33: =IF(Table3[[#This Row],[Collector3]]="","", _xlfn.LET(_xlpm.x,VLOOKUP(Table3[[#This Row],[Collector3]],'Drop-down_menus'!$F$2:$G$16,2,FALSE),IF(_xlpm.x=0,"",_xlpm.x))) | S33: =IF(Table3[[#This Row],[Collector4]]="","", _xlfn.LET(_xlpm.x,VLOOKUP(Table3[[#This Row],[Collector4]],'Drop-down_menus'!$F$2:$G$16,2,FALSE),IF(_xlpm.x=0,"",_xlpm.x))) | T33: 64°19,235 | U33: 62°55,418 | X33: 5 | Y33: 22 | AA33: 445 | AC33: Redo of DIV6 Test transect
A34: Melchior Island, North Omega | B34: https://data.aad.gov.au/aadc/gaz/scar/display_name.cfm?gaz_id=110104 | C34: DIV_7 | D34: =_xlfn.TEXTBEFORE(Table3[[#This Row],[eventID]],"_") -> DIV | E34: 45335 | G34: 0.64236111 | H34: 0.67708333 | I34: 15:25-03:00/16:15-03:00 | J34: 2024-02-13 | K34: =H34-G34 -> 0.034722222 | L34: Camille Moreau | M34: Lucas Terrana | P34: =IF(Table3[[#This Row],[Collector1]]="","", _xlfn.LET(_xlpm.x,VLOOKUP(Table3[[#This Row],[Collector1]],'Drop-down_menus'!$F$2:$G$16,2,FALSE),IF(_xlpm.x=0,"",_xlpm.x))) -> https://orcid.org/0000-0002-0981-7442 | Q34: =IF(Table3[[#This Row],[Collector2]]="","", _xlfn.LET(_xlpm.x,VLOOKUP(Table3[[#This Row],[Collector2]],'Drop-down_menus'!$F$2:$G$16,2,FALSE),IF(_xlpm.x=0,"",_xlpm.x))) -> https://orcid.org/0000-0001-5767-3220 | R34: =IF(Table3[[#This Row],[Collector3]]="","", _xlfn.LET(_xlpm.x,VLOOKUP(Table3[[#This Row],[Collector3]],'Drop-down_menus'!$F$2:$G$16,2,FALSE),IF(_xlpm.x=0,"",_xlpm.x))) | S34: =IF(Table3[[#This Row],[Collector4]]="","", _xlfn.LET(_xlpm.x,VLOOKUP(Table3[[#This Row],[Collector4]],'Drop-down_menus'!$F$2:$G$16,2,FALSE),IF(_xlpm.x=0,"",_xlpm.x))) | T34: 64°19,235 | U34: 62°55,418 | Y34: 21 | AA34: 441 | AB34: 444 | AC34: Meiofauna cores
A35: Melchior Island, North Omega | B35: https://data.aad.gov.au/aadc/gaz/scar/display_name.cfm?gaz_id=110104 | C35: NIS_17 | D35: =_xlfn.TEXTBEFORE(Table3[[#This Row],[eventID]],"_") -> NIS | E35: 45335 | G35: 0.60416667 | I35: 14:30-03:00 | J35: 2024-02-13 | L35: Axelle Brusselman | P35: =IF(Table3[[#This Row],[Collector1]]="","", _xlfn.LET(_xlpm.x,VLOOKUP(Table3[[#This Row],[Collector1]],'Drop-down_menus'!$F$2:$G$16,2,FALSE),IF(_xlpm.x=0,"",_xlpm.x))) -> https://orcid.org/0009-0002-6669-2911 | Q35: =IF(Table3[[#This Row],[Collector2]]="","", _xlfn.LET(_xlpm.x,VLOOKUP(Table3[[#This Row],[Collector2]],'Drop-down_menus'!$F$2:$G$16,2,FALSE),IF(_xlpm.x=0,"",_xlpm.x))) | R35: =IF(Table3[[#This Row],[Collector3]]="","", _xlfn.LET(_xlpm.x,VLOOKUP(Table3[[#This Row],[Collector3]],'Drop-down_menus'!$F$2:$G$16,2,FALSE),IF(_xlpm.x=0,"",_xlpm.x))) | S35: =IF(Table3[[#This Row],[Collector4]]="","", _xlfn.LET(_xlpm.x,VLOOKUP(Table3[[#This Row],[Collector4]],'Drop-down_menus'!$F$2:$G$16,2,FALSE),IF(_xlpm.x=0,"",_xlpm.x))) | T35: 64°19,235 | U35: 62°55,418 | AA35: 494 | AB35: 525
A36: Melchior Island, North Omega | B36: https://data.aad.gov.au/aadc/gaz/scar/display_name.cfm?gaz_id=110104 | C36: INC_1 | D36: =_xlfn.TEXTBEFORE(Table3[[#This Row],[eventID]],"_") -> INC | E36: 45335 | F36: 45336 | G36: 0.25 | H36: 0.33333333 | J36: 2024-02-13T06:00-03:00/2024-02-14T08:00-03:00 | K36: =-((E36+G36)-(F36+H36))*24 -> 26 | L36: Axelle Brusselman | P36: =IF(Table3[[#This Row],[Collector1]]="","", _xlfn.LET(_xlpm.x,VLOOKUP(Table3[[#This Row],[Collector1]],'Drop-down_menus'!$F$2:$G$16,2,FALSE),IF(_xlpm.x=0,"",_xlpm.x))) -> https://orcid.org/0009-0002-6669-2911 | Q36: =IF(Table3[[#This Row],[Collector2]]="","", _xlfn.LET(_xlpm.x,VLOOKUP(Table3[[#This Row],[Collector2]],'Drop-down_menus'!$F$2:$G$16,2,FALSE),IF(_xlpm.x=0,"",_xlpm.x))) | R36: =IF(Table3[[#This Row],[Collector3]]="","", _xlfn.LET(_xlpm.x,VLOOKUP(Table3[[#This Row],[Collector3]],'Drop-down_menus'!$F$2:$G$16,2,FALSE),IF(_xlpm.x=0,"",_xlpm.x))) | S36: =IF(Table3[[#This Row],[Collector4]]="","", _xlfn.LET(_xlpm.x,VLOOKUP(Table3[[#This Row],[Collector4]],'Drop-down_menus'!$F$2:$G$16,2,FALSE),IF(_xlpm.x=0,"",_xlpm.x))) | T36: 64°19,235 | U36: 62°55,418 | X36: 0 | Y36: 17 | AA36: 526 | AB36: 540 | AC36: 13C Incubations
A37: Melchior Island, North Omega | B37: https://data.aad.gov.au/aadc/gaz/scar/display_name.cfm?gaz_id=110104 | C37: ROV_5 | D37: =_xlfn.TEXTBEFORE(Table3[[#This Row],[eventID]],"_") -> ROV | E37: 45335 | G37: 0.66666667 | H37: 0.6875 | I37: 16:00-03:00/16:30-03:00 | J37: 2024-02-13 | K37: =H37-G37 -> 0.020833333 | L37: Lea Katz | M37: Henri Robert | P37: =IF(Table3[[#This Row],[Collector1]]="","", _xlfn.LET(_xlpm.x,VLOOKUP(Table3[[#This Row],[Collector1]],'Drop-down_menus'!$F$2:$G$16,2,FALSE),IF(_xlpm.x=0,"",_xlpm.x))) -> https://orcid.org/0000-0001-5748-602X | Q37: =IF(Table3[[#This Row],[Collector2]]="","", _xlfn.LET(_xlpm.x,VLOOKUP(Table3[[#This Row],[Collector2]],'Drop-down_menus'!$F$2:$G$16,2,FALSE),IF(_xlpm.x=0,"",_xlpm.x))) | R37: =IF(Table3[[#This Row],[Collector3]]="","", _xlfn.LET(_xlpm.x,VLOOKUP(Table3[[#This Row],[Collector3]],'Drop-down_menus'!$F$2:$G$16,2,FALSE),IF(_xlpm.x=0,"",_xlpm.x))) | S37: =IF(Table3[[#This Row],[Collector4]]="","", _xlfn.LET(_xlpm.x,VLOOKUP(Table3[[#This Row],[Collector4]],'Drop-down_menus'!$F$2:$G$16,2,FALSE),IF(_xlpm.x=0,"",_xlpm.x))) | T37: 64°19,235 | U37: 62°55,418 | X37: 5 | Y37: 20 | AA37: 446 | AB37: 447 | AC37: 2 transects, Leak detected
A38: Melchior Island, North Omega | B38: https://data.aad.gov.au/aadc/gaz/scar/display_name.cfm?gaz_id=110104 | C38: RD_3 | D38: =_xlfn.TEXTBEFORE(Table3[[#This Row],[eventID]],"_") -> RD | E38: 45336 | G38: 0.34722222 | H38: 0.36111111 | I38: 08:20-03:00/08:40-03:00 | J38: 2024-02-14 | K38: =H38-G38 -> 0.013888889 | L38: Henri Robert | P38: =IF(Table3[[#This Row],[Collector1]]="","", _xlfn.LET(_xlpm.x,VLOOKUP(Table3[[#This Row],[Collector1]],'Drop-down_menus'!$F$2:$G$16,2,FALSE),IF(_xlpm.x=0,"",_xlpm.x))) | Q38: =IF(Table3[[#This Row],[Collector2]]="","", _xlfn.LET(_xlpm.x,VLOOKUP(Table3[[#This Row],[Collector2]],'Drop-down_menus'!$F$2:$G$16,2,FALSE),IF(_xlpm.x=0,"",_xlpm.x))) | R38: =IF(Table3[[#This Row],[Collector3]]="","", _xlfn.LET(_xlpm.x,VLOOKUP(Table3[[#This Row],[Collector3]],'Drop-down_menus'!$F$2:$G$16,2,FALSE),IF(_xlpm.x=0,"",_xlpm.x))) | S38: =IF(Table3[[#This Row],[Collector4]]="","", _xlfn.LET(_xlpm.x,VLOOKUP(Table3[[#This Row],[Collector4]],'Drop-down_menus'!$F$2:$G$16,2,FALSE),IF(_xlpm.x=0,"",_xlpm.x))) | T38: 64°19,198 | U38: 62°55,115 | V38: 64°19,164 | W38: 62°54,881 | X38: 18 | Y38: 22 | AA38: 727 | AB38: 740
A39: Melchior Island, South Omega | B39: https://data.aad.gov.au/aadc/gaz/scar/display_name.cfm?gaz_id=110104 | C39: DIV_8 | D39: =_xlfn.TEXTBEFORE(Table3[[#This Row],[eventID]],"_") -> DIV | E39: 45336 | G39: 0.44097222 | H39: 0.47152778 | I39: 10:35-03:00/11:19-03:00 | J39: 2024-02-14 | K39: =H39-G39 -> 0.030555556 | L39: Lea Katz | M39: Martin Dogniez | P39: =IF(Table3[[#This Row],[Collector1]]="","", _xlfn.LET(_xlpm.x,VLOOKUP(Table3[[#This Row],[Collector1]],'Drop-down_menus'!$F$2:$G$16,2,FALSE),IF(_xlpm.x=0,"",_xlpm.x))) -> https://orcid.org/0000-0001-5748-602X | Q39: =IF(Table3[[#This Row],[Collector2]]="","", _xlfn.LET(_xlpm.x,VLOOKUP(Table3[[#This Row],[Collector2]],'Drop-down_menus'!$F$2:$G$16,2,FALSE),IF(_xlpm.x=0,"",_xlpm.x))) -> https://orcid.org/0000-0002-9708-1761 | R39: =IF(Table3[[#This Row],[Collector3]]="","", _xlfn.LET(_xlpm.x,VLOOKUP(Table3[[#This Row],[Collector3]],'Drop-down_menus'!$F$2:$G$16,2,FALSE),IF(_xlpm.x=0,"",_xlpm.x))) | S39: =IF(Table3[[#This Row],[Collector4]]="","", _xlfn.LET(_xlpm.x,VLOOKUP(Table3[[#This Row],[Collector4]],'Drop-down_menus'!$F$2:$G$16,2,FALSE),IF(_xlpm.x=0,"",_xlpm.x))) | T39: 64°20,4257 | U39: 62°57,0102 | Y39: 29 | AA39: 741 | AC39: Sea urchins Survey
A40: Melchior Island, South Omega | B40: https://data.aad.gov.au/aadc/gaz/scar/display_name.cfm?gaz_id=110104 | C40: ROV_6 | D40: =_xlfn.TEXTBEFORE(Table3[[#This Row],[eventID]],"_") -> ROV | E40: 45336 | G40: 0.59722222 | H40: 0.60416667 | I40: 14:20-03:00/14:30-03:00 | J40: 2024-02-14 | K40: =H40-G40 -> 0.0069444444 | L40: Lea Katz | M40: Henri Robert | P40: =IF(Table3[[#This Row],[Collector1]]="","", _xlfn.LET(_xlpm.x,VLOOKUP(Table3[[#This Row],[Collector1]],'Drop-down_menus'!$F$2:$G$16,2,FALSE),IF(_xlpm.x=0,"",_xlpm.x))) -> https://orcid.org/0000-0001-5748-602X | Q40: =IF(Table3[[#This Row],[Collector2]]="","", _xlfn.LET(_xlpm.x,VLOOKUP(Table3[[#This Row],[Collector2]],'Drop-down_menus'!$F$2:$G$16,2,FALSE),IF(_xlpm.x=0,"",_xlpm.x))) | R40: =IF(Table3[[#This Row],[Collector3]]="","", _xlfn.LET(_xlpm.x,VLOOKUP(Table3[[#This Row],[Collector3]],'Drop-down_menus'!$F$2:$G$16,2,FALSE),IF(_xlpm.x=0,"",_xlpm.x))) | S40: =IF(Table3[[#This Row],[Collector4]]="","", _xlfn.LET(_xlpm.x,VLOOKUP(Table3[[#This Row],[Collector4]],'Drop-down_menus'!$F$2:$G$16,2,FALSE),IF(_xlpm.x=0,"",_xlpm.x))) | T40: 64°20,4257 | U40: 62°57,0102 | AA40: 823 | AB40: 825 | AC40: Leak detected
...

Sheet Samples
A1: EventID | B1: ParentSampleID | C1: SampleID | D1: sampleType | E1: Parameter | F1: verbatimScientificName | G1: individualCount | H1: verbatimIdentification | I1: scientificName | J1: scientificNameAuthorship | K1: scientificNameID | L1: kingdom | M1: phylum | N1: class | O1: order | P1: family | Q1: genus | R1: specificEpithet | S1: taxonRank | T1: identifiedBy1 | U1: identifiedBy2 | V1: identifiedBy3 | W1: identifiedBy4 | X1: identifiedByID1 | Y1: identifiedByID2 | Z1: identifiedByID3 | AA1: identifiedByID4 | AB1: preservedIn1 | AC1: preservedIn2 | AD1: preservedIn3 | AE1: Container1 | AF1: Container2 | AG1: Container3 | AH1: Remark | AI1: recordedBy1 | AJ1: tangoProject | AK1: occurrenceRemarks
A2: RD_1 | C2: 152 | D2: biota | F2: Porifera | G2: 15 | H2: Porifera | I2: Porifera | J2: =IF($I2="","",_xlfn.LET(_xlpm.x,VLOOKUP($I2,'taxon-match_2026-08-31'!$A$2:$N$122,6,FALSE),IF(_xlpm.x=0,"",_xlpm.x))) -> Grant, 1836 | K2: =IF($I2="","",_xlfn.LET(_xlpm.x,VLOOKUP($I2,'taxon-match_2026-08-31'!$A$2:$N$122,4,FALSE),IF(_xlpm.x=0,"",_xlpm.x))) -> urn:lsid:marinespecies.org:taxname:558 | L2: =IF($I2="","",_xlfn.LET(_xlpm.x,VLOOKUP($I2,'taxon-match_2026-08-31'!$A$2:$N$122,7,FALSE),IF(_xlpm.x=0,"",_xlpm.x))) -> Animalia | M2: =IF($I2="","",_xlfn.LET(_xlpm.x,VLOOKUP($I2,'taxon-match_2026-08-31'!$A$2:$N$122,8,FALSE),IF(_xlpm.x=0,"",_xlpm.x))) -> Porifera | N2: =IF($I2="","",_xlfn.LET(_xlpm.x,VLOOKUP($I2,'taxon-match_2026-08-31'!$A$2:$N$122,9,FALSE),IF(_xlpm.x=0,"",_xlpm.x))) | O2: =IF($I2="","",_xlfn.LET(_xlpm.x,VLOOKUP($I2,'taxon-match_2026-08-31'!$A$2:$N$122,10,FALSE),IF(_xlpm.x=0,"",_xlpm.x))) | P2: =IF($I2="","",_xlfn.LET(_xlpm.x,VLOOKUP($I2,'taxon-match_2026-08-31'!$A$2:$N$122,11,FALSE),IF(_xlpm.x=0,"",_xlpm.x))) | Q2: =IF($I2="","",_xlfn.LET(_xlpm.x,VLOOKUP($I2,'taxon-match_2026-08-31'!$A$2:$N$122,12,FALSE),IF(_xlpm.x=0,"",_xlpm.x))) | R2: =IF($I2="","",_xlfn.LET(_xlpm.x,VLOOKUP($I2,'taxon-match_2026-08-31'!$A$2:$N$122,14,FALSE),IF(_xlpm.x=0,"",_xlpm.x))) | S2: phylum | T2: Henri Robert | U2: Camille Moreau | X2: =IF(T2="","",_xlfn.LET(_xlpm.x,VLOOKUP(T2,'Drop-down_menus'!$F$2:$G$16,2,FALSE),IF(_xlpm.x=0,"",_xlpm.x))) | Y2: =IF(U2="","",_xlfn.LET(_xlpm.x,VLOOKUP(U2,'Drop-down_menus'!$F$2:$G$16,2,FALSE),IF(_xlpm.x=0,"",_xlpm.x))) -> https://orcid.org/0000-0002-0981-7442 | Z2: =IF(V2="","",_xlfn.LET(_xlpm.x,VLOOKUP(V2,'Drop-down_menus'!$F$2:$G$16,2,FALSE),IF(_xlpm.x=0,"",_xlpm.x))) | AA2: =IF(W2="","",_xlfn.LET(_xlpm.x,VLOOKUP(W2,'Drop-down_menus'!$F$2:$G$16,2,FALSE),IF(_xlpm.x=0,"",_xlpm.x))) | AB2: Ethanol 96 | AF2: Kautex 100 ml | AI2: Bruno Danis | AJ2: BIODIVERSITY_MEGABENTHOS
A3: RD_1 | C3: 153 | D3: biota | F3: Invertebrata | H3: Invertebrata | I3: Biota | J3: =IF($I3="","",_xlfn.LET(_xlpm.x,VLOOKUP($I3,'taxon-match_2026-08-31'!$A$2:$N$122,6,FALSE),IF(_xlpm.x=0,"",_xlpm.x))) | K3: =IF($I3="","",_xlfn.LET(_xlpm.x,VLOOKUP($I3,'taxon-match_2026-08-31'!$A$2:$N$122,4,FALSE),IF(_xlpm.x=0,"",_xlpm.x))) -> urn:lsid:marinespecies.org:taxname:1 | L3: =IF($I3="","",_xlfn.LET(_xlpm.x,VLOOKUP($I3,'taxon-match_2026-08-31'!$A$2:$N$122,7,FALSE),IF(_xlpm.x=0,"",_xlpm.x))) | M3: =IF($I3="","",_xlfn.LET(_xlpm.x,VLOOKUP($I3,'taxon-match_2026-08-31'!$A$2:$N$122,8,FALSE),IF(_xlpm.x=0,"",_xlpm.x))) | N3: =IF($I3="","",_xlfn.LET(_xlpm.x,VLOOKUP($I3,'taxon-match_2026-08-31'!$A$2:$N$122,9,FALSE),IF(_xlpm.x=0,"",_xlpm.x))) | O3: =IF($I3="","",_xlfn.LET(_xlpm.x,VLOOKUP($I3,'taxon-match_2026-08-31'!$A$2:$N$122,10,FALSE),IF(_xlpm.x=0,"",_xlpm.x))) | P3: =IF($I3="","",_xlfn.LET(_xlpm.x,VLOOKUP($I3,'taxon-match_2026-08-31'!$A$2:$N$122,11,FALSE),IF(_xlpm.x=0,"",_xlpm.x))) | Q3: =IF($I3="","",_xlfn.LET(_xlpm.x,VLOOKUP($I3,'taxon-match_2026-08-31'!$A$2:$N$122,12,FALSE),IF(_xlpm.x=0,"",_xlpm.x))) | R3: =IF($I3="","",_xlfn.LET(_xlpm.x,VLOOKUP($I3,'taxon-match_2026-08-31'!$A$2:$N$122,14,FALSE),IF(_xlpm.x=0,"",_xlpm.x))) | S3: superdomain | T3: Henri Robert | U3: Camille Moreau | V3: Emil De Borger | X3: =IF(T3="","",_xlfn.LET(_xlpm.x,VLOOKUP(T3,'Drop-down_menus'!$F$2:$G$16,2,FALSE),IF(_xlpm.x=0,"",_xlpm.x))) | Y3: =IF(U3="","",_xlfn.LET(_xlpm.x,VLOOKUP(U3,'Drop-down_menus'!$F$2:$G$16,2,FALSE),IF(_xlpm.x=0,"",_xlpm.x))) -> https://orcid.org/0000-0002-0981-7442 | Z3: =IF(V3="","",_xlfn.LET(_xlpm.x,VLOOKUP(V3,'Drop-down_menus'!$F$2:$G$16,2,FALSE),IF(_xlpm.x=0,"",_xlpm.x))) -> https://orcid.org/0000-0003-4905-1637 | AA3: =IF(W3="","",_xlfn.LET(_xlpm.x,VLOOKUP(W3,'Drop-down_menus'!$F$2:$G$16,2,FALSE),IF(_xlpm.x=0,"",_xlpm.x))) | AB3: Ethanol 96 | AF3: Kautex 100 ml | AH3: Unsorted | AI3: Bruno Danis | AJ3: BIODIVERSITY_MEGABENTHOS
A4: RD_1 | C4: 154 | D4: biota | F4: Invertebrata | H4: Invertebrata | I4: Biota | J4: =IF($I4="","",_xlfn.LET(_xlpm.x,VLOOKUP($I4,'taxon-match_2026-08-31'!$A$2:$N$122,6,FALSE),IF(_xlpm.x=0,"",_xlpm.x))) | K4: =IF($I4="","",_xlfn.LET(_xlpm.x,VLOOKUP($I4,'taxon-match_2026-08-31'!$A$2:$N$122,4,FALSE),IF(_xlpm.x=0,"",_xlpm.x))) -> urn:lsid:marinespecies.org:taxname:1 | L4: =IF($I4="","",_xlfn.LET(_xlpm.x,VLOOKUP($I4,'taxon-match_2026-08-31'!$A$2:$N$122,7,FALSE),IF(_xlpm.x=0,"",_xlpm.x))) | M4: =IF($I4="","",_xlfn.LET(_xlpm.x,VLOOKUP($I4,'taxon-match_2026-08-31'!$A$2:$N$122,8,FALSE),IF(_xlpm.x=0,"",_xlpm.x))) | N4: =IF($I4="","",_xlfn.LET(_xlpm.x,VLOOKUP($I4,'taxon-match_2026-08-31'!$A$2:$N$122,9,FALSE),IF(_xlpm.x=0,"",_xlpm.x))) | O4: =IF($I4="","",_xlfn.LET(_xlpm.x,VLOOKUP($I4,'taxon-match_2026-08-31'!$A$2:$N$122,10,FALSE),IF(_xlpm.x=0,"",_xlpm.x))) | P4: =IF($I4="","",_xlfn.LET(_xlpm.x,VLOOKUP($I4,'taxon-match_2026-08-31'!$A$2:$N$122,11,FALSE),IF(_xlpm.x=0,"",_xlpm.x))) | Q4: =IF($I4="","",_xlfn.LET(_xlpm.x,VLOOKUP($I4,'taxon-match_2026-08-31'!$A$2:$N$122,12,FALSE),IF(_xlpm.x=0,"",_xlpm.x))) | R4: =IF($I4="","",_xlfn.LET(_xlpm.x,VLOOKUP($I4,'taxon-match_2026-08-31'!$A$2:$N$122,14,FALSE),IF(_xlpm.x=0,"",_xlpm.x))) | S4: superdomain | T4: Henri Robert | U4: Camille Moreau | V4: Emil De Borger | X4: =IF(T4="","",_xlfn.LET(_xlpm.x,VLOOKUP(T4,'Drop-down_menus'!$F$2:$G$16,2,FALSE),IF(_xlpm.x=0,"",_xlpm.x))) | Y4: =IF(U4="","",_xlfn.LET(_xlpm.x,VLOOKUP(U4,'Drop-down_menus'!$F$2:$G$16,2,FALSE),IF(_xlpm.x=0,"",_xlpm.x))) -> https://orcid.org/0000-0002-0981-7442 | Z4: =IF(V4="","",_xlfn.LET(_xlpm.x,VLOOKUP(V4,'Drop-down_menus'!$F$2:$G$16,2,FALSE),IF(_xlpm.x=0,"",_xlpm.x))) -> https://orcid.org/0000-0003-4905-1637 | AA4: =IF(W4="","",_xlfn.LET(_xlpm.x,VLOOKUP(W4,'Drop-down_menus'!$F$2:$G$16,2,FALSE),IF(_xlpm.x=0,"",_xlpm.x))) | AB4: Ethanol 96 | AF4: Kautex 100 ml | AH4: Unsorted | AI4: Bruno Danis | AJ4: BIODIVERSITY_MEGABENTHOS
A5: RD_1 | C5: 155 | D5: biota | F5: Algae | G5: 1 | H5: Algae | I5: Biota | J5: =IF($I5="","",_xlfn.LET(_xlpm.x,VLOOKUP($I5,'taxon-match_2026-08-31'!$A$2:$N$122,6,FALSE),IF(_xlpm.x=0,"",_xlpm.x))) | K5: =IF($I5="","",_xlfn.LET(_xlpm.x,VLOOKUP($I5,'taxon-match_2026-08-31'!$A$2:$N$122,4,FALSE),IF(_xlpm.x=0,"",_xlpm.x))) -> urn:lsid:marinespecies.org:taxname:1 | L5: =IF($I5="","",_xlfn.LET(_xlpm.x,VLOOKUP($I5,'taxon-match_2026-08-31'!$A$2:$N$122,7,FALSE),IF(_xlpm.x=0,"",_xlpm.x))) | M5: =IF($I5="","",_xlfn.LET(_xlpm.x,VLOOKUP($I5,'taxon-match_2026-08-31'!$A$2:$N$122,8,FALSE),IF(_xlpm.x=0,"",_xlpm.x))) | N5: =IF($I5="","",_xlfn.LET(_xlpm.x,VLOOKUP($I5,'taxon-match_2026-08-31'!$A$2:$N$122,9,FALSE),IF(_xlpm.x=0,"",_xlpm.x))) | O5: =IF($I5="","",_xlfn.LET(_xlpm.x,VLOOKUP($I5,'taxon-match_2026-08-31'!$A$2:$N$122,10,FALSE),IF(_xlpm.x=0,"",_xlpm.x))) | P5: =IF($I5="","",_xlfn.LET(_xlpm.x,VLOOKUP($I5,'taxon-match_2026-08-31'!$A$2:$N$122,11,FALSE),IF(_xlpm.x=0,"",_xlpm.x))) | Q5: =IF($I5="","",_xlfn.LET(_xlpm.x,VLOOKUP($I5,'taxon-match_2026-08-31'!$A$2:$N$122,12,FALSE),IF(_xlpm.x=0,"",_xlpm.x))) | R5: =IF($I5="","",_xlfn.LET(_xlpm.x,VLOOKUP($I5,'taxon-match_2026-08-31'!$A$2:$N$122,14,FALSE),IF(_xlpm.x=0,"",_xlpm.x))) | S5: superdomain | T5: Henri Robert | U5: Camille Moreau | V5: Emil De Borger | X5: =IF(T5="","",_xlfn.LET(_xlpm.x,VLOOKUP(T5,'Drop-down_menus'!$F$2:$G$16,2,FALSE),IF(_xlpm.x=0,"",_xlpm.x))) | Y5: =IF(U5="","",_xlfn.LET(_xlpm.x,VLOOKUP(U5,'Drop-down_menus'!$F$2:$G$16,2,FALSE),IF(_xlpm.x=0,"",_xlpm.x))) -> https://orcid.org/0000-0002-0981-7442 | Z5: =IF(V5="","",_xlfn.LET(_xlpm.x,VLOOKUP(V5,'Drop-down_menus'!$F$2:$G$16,2,FALSE),IF(_xlpm.x=0,"",_xlpm.x))) -> https://orcid.org/0000-0003-4905-1637 | AA5: =IF(W5="","",_xlfn.LET(_xlpm.x,VLOOKUP(W5,'Drop-down_menus'!$F$2:$G$16,2,FALSE),IF(_xlpm.x=0,"",_xlpm.x))) | AB5: Ethanol 96 | AF5: Glass Vial 20 ml | AI5: Bruno Danis | AJ5: BIODIVERSITY_MEGABENTHOS
A6: RD_1 | C6: 156 | D6: biota | F6: Algae | G6: 5 | H6: Algae | I6: Biota | J6: =IF($I6="","",_xlfn.LET(_xlpm.x,VLOOKUP($I6,'taxon-match_2026-08-31'!$A$2:$N$122,6,FALSE),IF(_xlpm.x=0,"",_xlpm.x))) | K6: =IF($I6="","",_xlfn.LET(_xlpm.x,VLOOKUP($I6,'taxon-match_2026-08-31'!$A$2:$N$122,4,FALSE),IF(_xlpm.x=0,"",_xlpm.x))) -> urn:lsid:marinespecies.org:taxname:1 | L6: =IF($I6="","",_xlfn.LET(_xlpm.x,VLOOKUP($I6,'taxon-match_2026-08-31'!$A$2:$N$122,7,FALSE),IF(_xlpm.x=0,"",_xlpm.x))) | M6: =IF($I6="","",_xlfn.LET(_xlpm.x,VLOOKUP($I6,'taxon-match_2026-08-31'!$A$2:$N$122,8,FALSE),IF(_xlpm.x=0,"",_xlpm.x))) | N6: =IF($I6="","",_xlfn.LET(_xlpm.x,VLOOKUP($I6,'taxon-match_2026-08-31'!$A$2:$N$122,9,FALSE),IF(_xlpm.x=0,"",_xlpm.x))) | O6: =IF($I6="","",_xlfn.LET(_xlpm.x,VLOOKUP($I6,'taxon-match_2026-08-31'!$A$2:$N$122,10,FALSE),IF(_xlpm.x=0,"",_xlpm.x))) | P6: =IF($I6="","",_xlfn.LET(_xlpm.x,VLOOKUP($I6,'taxon-match_2026-08-31'!$A$2:$N$122,11,FALSE),IF(_xlpm.x=0,"",_xlpm.x))) | Q6: =IF($I6="","",_xlfn.LET(_xlpm.x,VLOOKUP($I6,'taxon-match_2026-08-31'!$A$2:$N$122,12,FALSE),IF(_xlpm.x=0,"",_xlpm.x))) | R6: =IF($I6="","",_xlfn.LET(_xlpm.x,VLOOKUP($I6,'taxon-match_2026-08-31'!$A$2:$N$122,14,FALSE),IF(_xlpm.x=0,"",_xlpm.x))) | S6: superdomain | T6: Henri Robert | U6: Camille Moreau | V6: Emil De Borger | X6: =IF(T6="","",_xlfn.LET(_xlpm.x,VLOOKUP(T6,'Drop-down_menus'!$F$2:$G$16,2,FALSE),IF(_xlpm.x=0,"",_xlpm.x))) | Y6: =IF(U6="","",_xlfn.LET(_xlpm.x,VLOOKUP(U6,'Drop-down_menus'!$F$2:$G$16,2,FALSE),IF(_xlpm.x=0,"",_xlpm.x))) -> https://orcid.org/0000-0002-0981-7442 | Z6: =IF(V6="","",_xlfn.LET(_xlpm.x,VLOOKUP(V6,'Drop-down_menus'!$F$2:$G$16,2,FALSE),IF(_xlpm.x=0,"",_xlpm.x))) -> https://orcid.org/0000-0003-4905-1637 | AA6: =IF(W6="","",_xlfn.LET(_xlpm.x,VLOOKUP(W6,'Drop-down_menus'!$F$2:$G$16,2,FALSE),IF(_xlpm.x=0,"",_xlpm.x))) | AB6: Ethanol 96 | AF6: Glass Vial 20 ml | AI6: Bruno Danis | AJ6: BIODIVERSITY_MEGABENTHOS
